因为方法后面声明了异常（throws exception），如果该方法里有try catch对出现的异常进行捕获、处理。如果没有捕获方法，该方法就会将异常往上抛出，在调用该方法的方法里找，就这样一直抛，如果都没有，就给main方法，然后交由虚拟机来处理异常。因为处理语句前多写了一行 try{ 故异常输出最后一行的数字差一。